Workbook

Sheet Léame
A1: HOJA DE CAPTURA · RETORNO ESPERADO · DUSA CAI-035 (interna, no se entrega al cliente)
A3: Para qué sirve: reunir los datos duros por área y por proceso (volumen, tiempo actual, tiempo con la solución, horas recuperadas, dinero, dotación) que alimentan la página de «Retorno esperado» del informe y de la propuesta, con meta a 30, 60 y 90 días.
A4: Cómo se llena: celdas AZULES = dato a completar. Celdas GRISES = fórmula (no tocar). Cada dato lleva su «Tipo de dato»: Medido, Declarado por el área o Estimación conservadora. Las estimaciones se indican como tales en el documento final.
A5: Regla de oro: no se completa nada por intuición. Si el dato no existe, se deja vacío; el documento mostrará una estimación conservadora marcada como tal, o no mostrará la cifra.
A7: Qué se encontró al preparar esta hoja (importante):
A8: 1) Las fichas de levantamiento disponibles (Nómina, Servicio Médico y Agente de Parafiscales) dicen «No declarado» en volumen mensual y horas por ejecución para casi todos los procesos. La propia ficha de Nómina indica que «ninguna estimación de ahorro es defendible» antes de la descripción paso a paso del equipo.
A9: 2) Por eso las columnas de tiempo, dinero y dotación están vacías. Los datos que sí existen están en la hoja «Datos disponibles», cada uno con su fuente.
A10: 3) Faltan, para calcular dinero y posiciones: costo hora de referencia (validado con Wilmer), horas productivas por posición al mes, escalas salariales de DUSA, dotación equivalente por área (solo se conoce Cuentas por Cobrar: ≈8 personas) y los montos de retrabajo, errores y pagos o cobros tardíos.
A11: 4) Los montos de la ficha del agente de parafiscales (p. ej. 23.751,77 de totales anteriores no pagados del Seguro Social) no traen moneda; la magnitud sugiere bolívares. Confirmar antes de usarlos.
A13: Hojas: Parámetros · Retorno por proceso (44 soluciones) · Resumen por área (fórmulas) · Dotación y nómina · Sistemas · Datos disponibles · Datos que faltan.

Sheet Parámetros
A1: Parámetro | B1: Valor | C1: Cómo se obtiene / quién lo valida
A2: Costo hora de referencia (USD por hora) | C2: Se valida con Wilmer. Sin este dato no se calcula el valor de las horas recuperadas.
A3: Horas productivas por posición al mes | C3: Define cuántas horas recuperadas equivalen a una posición. Validar con Recursos Humanos de DUSA (no se asume).
A4: Moneda de los montos de las fichas | C4: Las fichas de parafiscales no indican moneda. Confirmar con Nómina.
A5: Tasa de cambio de referencia (si hay montos en bolívares) | C5: Solo si se convierten montos a dólares; indicar fecha y fuente.
A6: Fecha de la referencia de costos | C6: Fecha en que se validaron el costo hora y las escalas salariales.

Sheet Retorno por proceso
A1: Área | B1: Carril | C1: Frente | D1: ID | E1: Solución / proceso (resumen) | F1: Horas de sesión (Intezia) | G1: Fase | H1: Volumen mensual | I1: Unidad del volumen | J1: Qué se sabe hoy (con fuente) | K1: Fuente | L1: Tiempo actual por ejecución (h) | M1: Ejecuciones al mes | N1: Horas actuales al mes | O1: Tiempo con la solución por ejecución (h) | P1: Horas con la solución al mes | Q1: Horas recuperadas al mes | R1: Valor de las horas recuperadas (USD/mes) | S1: Retrabajo y errores (USD/mes) | T1: Pagos o cobros tardíos (USD/mes) | U1: Retorno mensual (USD) | V1: Tipo de dato | W1: Meta a 30 días (h recuperadas/mes) | X1: Meta a 60 días | Y1: Meta a 90 días | Z1: Observación
A2: Contabilidad y Cuentas por Pagar | B2: Copilot | C2: C | D2: CP-1 | E2: Asistente de asignación y aprobación de pagos | F2: 14 | G2: F1 | J2: Más de 300 facturas al mes se registran a mano (el registro de facturas lo cubre Sistemas, no esta propuesta) | K2: Informe Final de Auditoría IA, 04/09/2026 | N2: =IF(AND(ISNUMBER(L2),ISNUMBER(M2)),L2*M2,"") | P2: =IF(AND(ISNUMBER(O2),ISNUMBER(M2)),O2*M2,"") | Q2: =IF(AND(ISNUMBER(N2),ISNUMBER(P2)),N2-P2,"") | R2: =IF(AND(ISNUMBER(Q2),ISNUMBER(Parámetros!$B$2)),Q2*Parámetros!$B$2,"") | U2: =IF(COUNT(R2:T2)=0,"",SUM(R2:T2))
A3: Contabilidad y Cuentas por Pagar | B3: Copilot | C3: C | D3: CP-2 | E3: Depurador de reportes exportados de JD Edwards | F3: 9 | G3: F1 | N3: =IF(AND(ISNUMBER(L3),ISNUMBER(M3)),L3*M3,"") | P3: =IF(AND(ISNUMBER(O3),ISNUMBER(M3)),O3*M3,"") | Q3: =IF(AND(ISNUMBER(N3),ISNUMBER(P3)),N3-P3,"") | R3: =IF(AND(ISNUMBER(Q3),ISNUMBER(Parámetros!$B$2)),Q3*Parámetros!$B$2,"") | U3: =IF(COUNT(R3:T3)=0,"",SUM(R3:T3))
A4: Contabilidad y Cuentas por Pagar | B4: Copilot | C4: C | D4: CP-3 | E4: Agente de estados financieros pulido y estandarizado para todo el equipo y extendido al ciclo (ver programa.md) | F4: 12 | G4: F2 | N4: =IF(AND(ISNUMBER(L4),ISNUMBER(M4)),L4*M4,"") | P4: =IF(AND(ISNUMBER(O4),ISNUMBER(M4)),O4*M4,"") | Q4: =IF(AND(ISNUMBER(N4),ISNUMBER(P4)),N4-P4,"") | R4: =IF(AND(ISNUMBER(Q4),ISNUMBER(Parámetros!$B$2)),Q4*Parámetros!$B$2,"") | U4: =IF(COUNT(R4:T4)=0,"",SUM(R4:T4))
A5: Tesorería | B5: Copilot | C5: C | D5: TS-1 | E5: Clasificador de la bandeja del tesorero | F5: 14 | G5: F1 | J5: 130 cuentas bancarias de 15 empresas; cerca de 5.000 movimientos al mes; la mitad de la jornada se va en descargar y cargar extractos | K5: Informe Final de Auditoría IA, 04/09/2026 (recogido en dusa-cai012/brief.md) | N5: =IF(AND(ISNUMBER(L5),ISNUMBER(M5)),L5*M5,"") | P5: =IF(AND(ISNUMBER(O5),ISNUMBER(M5)),O5*M5,"") | Q5: =IF(AND(ISNUMBER(N5),ISNUMBER(P5)),N5-P5,"") | R5: =IF(AND(ISNUMBER(Q5),ISNUMBER(Parámetros!$B$2)),Q5*Parámetros!$B$2,"") | U5: =IF(COUNT(R5:T5)=0,"",SUM(R5:T5))
A6: Tesorería | B6: Copilot | C6: C | D6: TS-2 | E6: Seguimiento de tareas del equipo y de las áreas que entregan insumos, sobre la herramienta de (ver programa.md) | F6: 8 | G6: F1 | N6: =IF(AND(ISNUMBER(L6),ISNUMBER(M6)),L6*M6,"") | P6: =IF(AND(ISNUMBER(O6),ISNUMBER(M6)),O6*M6,"") | Q6: =IF(AND(ISNUMBER(N6),ISNUMBER(P6)),N6-P6,"") | R6: =IF(AND(ISNUMBER(Q6),ISNUMBER(Parámetros!$B$2)),Q6*Parámetros!$B$2,"") | U6: =IF(COUNT(R6:T6)=0,"",SUM(R6:T6))
A7: Cuentas por Cobrar | B7: Copilot | C7: C | D7: CC-1 | E7: Cuadro nacional de descuentos comerciales normalizado por marca y conciliado contra pedido, (ver programa.md) | F7: 15 | G7: F1 | J7: La líder de Cuentas por Cobrar estimó unas 8 personas para procesar la data a mano | K7: Mensaje de revisión del 05/10/2026; verificar contra la ficha de Cuentas por Cobrar | N7: =IF(AND(ISNUMBER(L7),ISNUMBER(M7)),L7*M7,"") | P7: =IF(AND(ISNUMBER(O7),ISNUMBER(M7)),O7*M7,"") | Q7: =IF(AND(ISNUMBER(N7),ISNUMBER(P7)),N7-P7,"") | R7: =IF(AND(ISNUMBER(Q7),ISNUMBER(Parámetros!$B$2)),Q7*Parámetros!$B$2,"") | U7: =IF(COUNT(R7:T7)=0,"",SUM(R7:T7))
A8: Finanzas | B8: Copilot | C8: C | D8: FN-0 | E8: Mapeo de microprocesos con las cinco áreas proveedoras y contrato de datos por área | F8: 12 | G8: F0 | N8: =IF(AND(ISNUMBER(L8),ISNUMBER(M8)),L8*M8,"") | P8: =IF(AND(ISNUMBER(O8),ISNUMBER(M8)),O8*M8,"") | Q8: =IF(AND(ISNUMBER(N8),ISNUMBER(P8)),N8-P8,"") | R8: =IF(AND(ISNUMBER(Q8),ISNUMBER(Parámetros!$B$2)),Q8*Parámetros!$B$2,"") | U8: =IF(COUNT(R8:T8)=0,"",SUM(R8:T8))
A9: Finanzas | B9: Copilot | C9: C | D9: FN-1 | E9: Agente de presentación de premisas al comité, sin dependencia de terceros | F9: 7 | G9: F1 | N9: =IF(AND(ISNUMBER(L9),ISNUMBER(M9)),L9*M9,"") | P9: =IF(AND(ISNUMBER(O9),ISNUMBER(M9)),O9*M9,"") | Q9: =IF(AND(ISNUMBER(N9),ISNUMBER(P9)),N9-P9,"") | R9: =IF(AND(ISNUMBER(Q9),ISNUMBER(Parámetros!$B$2)),Q9*Parámetros!$B$2,"") | U9: =IF(COUNT(R9:T9)=0,"",SUM(R9:T9))
A10: Finanzas | B10: Copilot | C10: C | D10: FN-2 | E10: Plan de ventas (plan de licores) mensualizado por producto | F10: 9 | G10: F2 | N10: =IF(AND(ISNUMBER(L10),ISNUMBER(M10)),L10*M10,"") | P10: =IF(AND(ISNUMBER(O10),ISNUMBER(M10)),O10*M10,"") | Q10: =IF(AND(ISNUMBER(N10),ISNUMBER(P10)),N10-P10,"") | R10: =IF(AND(ISNUMBER(Q10),ISNUMBER(Parámetros!$B$2)),Q10*Parámetros!$B$2,"") | U10: =IF(COUNT(R10:T10)=0,"",SUM(R10:T10))
A11: Finanzas | B11: Copilot | C11: C | D11: FN-3 | E11: Costos de materiales y precios | F11: 10 | G11: F2 | N11: =IF(AND(ISNUMBER(L11),ISNUMBER(M11)),L11*M11,"") | P11: =IF(AND(ISNUMBER(O11),ISNUMBER(M11)),O11*M11,"") | Q11: =IF(AND(ISNUMBER(N11),ISNUMBER(P11)),N11-P11,"") | R11: =IF(AND(ISNUMBER(Q11),ISNUMBER(Parámetros!$B$2)),Q11*Parámetros!$B$2,"") | U11: =IF(COUNT(R11:T11)=0,"",SUM(R11:T11))
A12: Finanzas | B12: Copilot | C12: C | D12: FN-4 | E12: Plan administrativo | F12: 7 | G12: F2 | N12: =IF(AND(ISNUMBER(L12),ISNUMBER(M12)),L12*M12,"") | P12: =IF(AND(ISNUMBER(O12),ISNUMBER(M12)),O12*M12,"") | Q12: =IF(AND(ISNUMBER(N12),ISNUMBER(P12)),N12-P12,"") | R12: =IF(AND(ISNUMBER(Q12),ISNUMBER(Parámetros!$B$2)),Q12*Parámetros!$B$2,"") | U12: =IF(COUNT(R12:T12)=0,"",SUM(R12:T12))
A13: Finanzas | B13: Copilot | C13: C | D13: FN-5 | E13: Costeo de manufactura | F13: 14 | G13: F3 | N13: =IF(AND(ISNUMBER(L13),ISNUMBER(M13)),L13*M13,"") | P13: =IF(AND(ISNUMBER(O13),ISNUMBER(M13)),O13*M13,"") | Q13: =IF(AND(ISNUMBER(N13),ISNUMBER(P13)),N13-P13,"") | R13: =IF(AND(ISNUMBER(Q13),ISNUMBER(Parámetros!$B$2)),Q13*Parámetros!$B$2,"") | U13: =IF(COUNT(R13:T13)=0,"",SUM(R13:T13))
A14: Finanzas | B14: Copilot | C14: C | D14: FN-6 | E14: Integración del plan de nómina, construido por Nómina en NM-6, al modelo financiero | F14: 7 | G14: F3 | N14: =IF(AND(ISNUMBER(L14),ISNUMBER(M14)),L14*M14,"") | P14: =IF(AND(ISNUMBER(O14),ISNUMBER(M14)),O14*M14,"") | Q14: =IF(AND(ISNUMBER(N14),ISNUMBER(P14)),N14-P14,"") | R14: =IF(AND(ISNUMBER(Q14),ISNUMBER(Parámetros!$B$2)),Q14*Parámetros!$B$2,"") | U14: =IF(COUNT(R14:T14)=0,"",SUM(R14:T14))
A15: Finanzas | B15: Copilot | C15: C | D15: FN-7 | E15: Consolidación | F15: 14 | G15: F3 | N15: =IF(AND(ISNUMBER(L15),ISNUMBER(M15)),L15*M15,"") | P15: =IF(AND(ISNUMBER(O15),ISNUMBER(M15)),O15*M15,"") | Q15: =IF(AND(ISNUMBER(N15),ISNUMBER(P15)),N15-P15,"") | R15: =IF(AND(ISNUMBER(Q15),ISNUMBER(Parámetros!$B$2)),Q15*Parámetros!$B$2,"") | U15: =IF(COUNT(R15:T15)=0,"",SUM(R15:T15))
A16: Comercial Región Centro-Sur | B16: Copilot | C16: C | D16: CM-1 | E16: Generador de creativos extendido al ciclo completo de activación y degustación | F16: 5 | G16: F1 | N16: =IF(AND(ISNUMBER(L16),ISNUMBER(M16)),L16*M16,"") | P16: =IF(AND(ISNUMBER(O16),ISNUMBER(M16)),O16*M16,"") | Q16: =IF(AND(ISNUMBER(N16),ISNUMBER(P16)),N16-P16,"") | R16: =IF(AND(ISNUMBER(Q16),ISNUMBER(Parámetros!$B$2)),Q16*Parámetros!$B$2,"") | U16: =IF(COUNT(R16:T16)=0,"",SUM(R16:T16))
A17: Comercial Región Centro-Sur | B17: Copilot | C17: C | D17: CM-2 | E17: Gestor de descuentos por cliente | F17: 11 | G17: F2 | N17: =IF(AND(ISNUMBER(L17),ISNUMBER(M17)),L17*M17,"") | P17: =IF(AND(ISNUMBER(O17),ISNUMBER(M17)),O17*M17,"") | Q17: =IF(AND(ISNUMBER(N17),ISNUMBER(P17)),N17-P17,"") | R17: =IF(AND(ISNUMBER(Q17),ISNUMBER(Parámetros!$B$2)),Q17*Parámetros!$B$2,"") | U17: =IF(COUNT(R17:T17)=0,"",SUM(R17:T17))
A18: Comercial Región Centro-Sur | B18: Copilot | C18: C | D18: CM-3 | E18: Diseñador de cabezal y exhibición en punto de venta; requiere el inventario de material POP (ver programa.md) | F18: 5 | G18: F3 | N18: =IF(AND(ISNUMBER(L18),ISNUMBER(M18)),L18*M18,"") | P18: =IF(AND(ISNUMBER(O18),ISNUMBER(M18)),O18*M18,"") | Q18: =IF(AND(ISNUMBER(N18),ISNUMBER(P18)),N18-P18,"") | R18: =IF(AND(ISNUMBER(Q18),ISNUMBER(Parámetros!$B$2)),Q18*Parámetros!$B$2,"") | U18: =IF(COUNT(R18:T18)=0,"",SUM(R18:T18))
A19: Base de datos de empleados (proceso base) | B19: Claude Team | C19: A | D19: RH-0 | E19: Orden de la base de datos de empleados y su carga familiar, | F19: 19 | G19: F1 | J19: 5 fuentes sin dato común; ficha numerada por separado en 18 compañías; ≈2.200 trabajadores en la base de Nómina; 2.516 personas en la base de Servicio Médico | K19: Informe de Detección; fichas de Nómina y Servicio Médico | N19: =IF(AND(ISNUMBER(L19),ISNUMBER(M19)),L19*M19,"") | P19: =IF(AND(ISNUMBER(O19),ISNUMBER(M19)),O19*M19,"") | Q19: =IF(AND(ISNUMBER(N19),ISNUMBER(P19)),N19-P19,"") | R19: =IF(AND(ISNUMBER(Q19),ISNUMBER(Parámetros!$B$2)),Q19*Parámetros!$B$2,"") | U19: =IF(COUNT(R19:T19)=0,"",SUM(R19:T19))
A20: Nómina | B20: Claude Team | C20: A | D20: NM-1 | E20: Solicitudes de pago parafiscales (Seguro Social, FAOV, INCES, sindicato y pensiones) para 10 a (ver programa.md) | F20: 17 | G20: F1 | J20: 4 servicios (Seguro Social, FAOV, INCES, sindicato y pensiones) en 10 a 15 empresas, cada mes, en los primeros 5 días hábiles | K20: Ficha de levantamiento de Nómina, 01/10/2026. Horas por ejecución: No declarado | N20: =IF(AND(ISNUMBER(L20),ISNUMBER(M20)),L20*M20,"") | P20: =IF(AND(ISNUMBER(O20),ISNUMBER(M20)),O20*M20,"") | Q20: =IF(AND(ISNUMBER(N20),ISNUMBER(P20)),N20-P20,"") | R20: =IF(AND(ISNUMBER(Q20),ISNUMBER(Parámetros!$B$2)),Q20*Parámetros!$B$2,"") | U20: =IF(COUNT(R20:T20)=0,"",SUM(R20:T20))
A21: Nómina | B21: Claude Team | C21: A | D21: NM-2 | E21: Validador de vacaciones sobre la exportación semanal del control de SPI, primer contacto del (ver programa.md) | F21: 10 | G21: F1 | J21: Validación semanal, los lunes; volumen de solicitudes no declarado | K21: Ficha de Nómina, 01/10/2026 | N21: =IF(AND(ISNUMBER(L21),ISNUMBER(M21)),L21*M21,"") | P21: =IF(AND(ISNUMBER(O21),ISNUMBER(M21)),O21*M21,"") | Q21: =IF(AND(ISNUMBER(N21),ISNUMBER(P21)),N21-P21,"") | R21: =IF(AND(ISNUMBER(Q21),ISNUMBER(Parámetros!$B$2)),Q21*Parámetros!$B$2,"") | U21: =IF(COUNT(R21:T21)=0,"",SUM(R21:T21))
A22: Nómina | B22: Claude Team | C22: A | D22: NM-3 | E22: Notificaciones | F22: 15 | G22: F2 | J22: Retiros de fideicomiso semanales (abono los viernes); volumen no declarado | K22: Ficha de Nómina, 01/10/2026 | N22: =IF(AND(ISNUMBER(L22),ISNUMBER(M22)),L22*M22,"") | P22: =IF(AND(ISNUMBER(O22),ISNUMBER(M22)),O22*M22,"") | Q22: =IF(AND(ISNUMBER(N22),ISNUMBER(P22)),N22-P22,"") | R22: =IF(AND(ISNUMBER(Q22),ISNUMBER(Parámetros!$B$2)),Q22*Parámetros!$B$2,"") | U22: =IF(COUNT(R22:T22)=0,"",SUM(R22:T22))
A23: Nómina | B23: Claude Team | C23: A | D23: NM-4 | E23: Flujo completo de parafiscales con Registro y Tesorería | F23: 13 | G23: F2 | J23: Expediente por empresa y servicio; los soportes hoy quedan dispersos entre correos y una carpeta local | K23: Ficha de Nómina, 01/10/2026 | N23: =IF(AND(ISNUMBER(L23),ISNUMBER(M23)),L23*M23,"") | P23: =IF(AND(ISNUMBER(O23),ISNUMBER(M23)),O23*M23,"") | Q23: =IF(AND(ISNUMBER(N23),ISNUMBER(P23)),N23-P23,"") | R23: =IF(AND(ISNUMBER(Q23),ISNUMBER(Parámetros!$B$2)),Q23*Parámetros!$B$2,"") | U23: =IF(COUNT(R23:T23)=0,"",SUM(R23:T23))
A24: Nómina | B24: Claude Team | C24: A | D24: NM-5 | E24: Validador de préstamos | F24: 12 | G24: F3 | J24: Préstamos semanales; el sindicato administra cupos: 4 personales y 3 de electrodomésticos por semana, 6 de vivienda al mes | K24: Ficha de Nómina, 01/10/2026 | N24: =IF(AND(ISNUMBER(L24),ISNUMBER(M24)),L24*M24,"") | P24: =IF(AND(ISNUMBER(O24),ISNUMBER(M24)),O24*M24,"") | Q24: =IF(AND(ISNUMBER(N24),ISNUMBER(P24)),N24-P24,"") | R24: =IF(AND(ISNUMBER(Q24),ISNUMBER(Parámetros!$B$2)),Q24*Parámetros!$B$2,"") | U24: =IF(COUNT(R24:T24)=0,"",SUM(R24:T24))
A25: Nómina | B25: Claude Team | C25: A | D25: NM-6 | E25: Plan y presupuesto de nómina sobre la base de conocimiento laboral del líder (ley, convención, (ver programa.md) | F25: 15 | G25: F3 | N25: =IF(AND(ISNUMBER(L25),ISNUMBER(M25)),L25*M25,"") | P25: =IF(AND(ISNUMBER(O25),ISNUMBER(M25)),O25*M25,"") | Q25: =IF(AND(ISNUMBER(N25),ISNUMBER(P25)),N25-P25,"") | R25: =IF(AND(ISNUMBER(Q25),ISNUMBER(Parámetros!$B$2)),Q25*Parámetros!$B$2,"") | U25: =IF(COUNT(R25:T25)=0,"",SUM(R25:T25))
A26: Servicio Médico | B26: Claude Team | C26: A | D26: SM-1 | E26: Adopción por el equipo de los agentes de morbilidad (con familiares) y certificados de salud, (ver programa.md) | F26: 11 | G26: F1 | J26: Análisis de morbilidad mensual: casi una jornada por ejecución (manual). Certificados de salud a requerimiento: unos 3 días por informe (manual) | K26: Ficha de Servicio Médico, 01-02/10/2026. Los 10 minutos del agente no incluyen insumos ni revisión: no es ahorro neto | N26: =IF(AND(ISNUMBER(L26),ISNUMBER(M26)),L26*M26,"") | P26: =IF(AND(ISNUMBER(O26),ISNUMBER(M26)),O26*M26,"") | Q26: =IF(AND(ISNUMBER(N26),ISNUMBER(P26)),N26-P26,"") | R26: =IF(AND(ISNUMBER(Q26),ISNUMBER(Parámetros!$B$2)),Q26*Parámetros!$B$2,"") | U26: =IF(COUNT(R26:T26)=0,"",SUM(R26:T26))
A27: Servicio Médico | B27: Claude Team | C27: A | D27: SM-2 | E27: Tratamiento crónico | F27: 15 | G27: F1 | J27: Despacho mensual del tratamiento crónico: 1.471 medicamentos en el pedido | K27: Ficha de Servicio Médico, 01-02/10/2026 | N27: =IF(AND(ISNUMBER(L27),ISNUMBER(M27)),L27*M27,"") | P27: =IF(AND(ISNUMBER(O27),ISNUMBER(M27)),O27*M27,"") | Q27: =IF(AND(ISNUMBER(N27),ISNUMBER(P27)),N27-P27,"") | R27: =IF(AND(ISNUMBER(Q27),ISNUMBER(Parámetros!$B$2)),Q27*Parámetros!$B$2,"") | U27: =IF(COUNT(R27:T27)=0,"",SUM(R27:T27))
A28: Servicio Médico | B28: Claude Team | C28: A | D28: SM-3 | E28: Trazabilidad de órdenes de referencia | F28: 12 | G28: F2 | N28: =IF(AND(ISNUMBER(L28),ISNUMBER(M28)),L28*M28,"") | P28: =IF(AND(ISNUMBER(O28),ISNUMBER(M28)),O28*M28,"") | Q28: =IF(AND(ISNUMBER(N28),ISNUMBER(P28)),N28-P28,"") | R28: =IF(AND(ISNUMBER(Q28),ISNUMBER(Parámetros!$B$2)),Q28*Parámetros!$B$2,"") | U28: =IF(COUNT(R28:T28)=0,"",SUM(R28:T28))
A29: Servicio Médico | B29: Claude Team | C29: A | D29: SM-4 | E29: Prevalidación documental | F29: 14 | G29: F2 | J29: Base de 2.516 personas (beneficiarios) | K29: Ficha de Servicio Médico, 01-02/10/2026 | N29: =IF(AND(ISNUMBER(L29),ISNUMBER(M29)),L29*M29,"") | P29: =IF(AND(ISNUMBER(O29),ISNUMBER(M29)),O29*M29,"") | Q29: =IF(AND(ISNUMBER(N29),ISNUMBER(P29)),N29-P29,"") | R29: =IF(AND(ISNUMBER(Q29),ISNUMBER(Parámetros!$B$2)),Q29*Parámetros!$B$2,"") | U29: =IF(COUNT(R29:T29)=0,"",SUM(R29:T29))
A30: Servicio Médico | B30: Claude Team | C30: A | D30: SM-5 | E30: Coberturas y costo consolidado por beneficiario (servicio médico y HCM), con alerta de (ver programa.md) | F30: 11 | G30: F3 | N30: =IF(AND(ISNUMBER(L30),ISNUMBER(M30)),L30*M30,"") | P30: =IF(AND(ISNUMBER(O30),ISNUMBER(M30)),O30*M30,"") | Q30: =IF(AND(ISNUMBER(N30),ISNUMBER(P30)),N30-P30,"") | R30: =IF(AND(ISNUMBER(Q30),ISNUMBER(Parámetros!$B$2)),Q30*Parámetros!$B$2,"") | U30: =IF(COUNT(R30:T30)=0,"",SUM(R30:T30))
A31: Gestión Contable RRHH | B31: Claude Team | C31: A | D31: GC-1 | E31: Registro completo de facturas de salud | F31: 15 | G31: F1 | N31: =IF(AND(ISNUMBER(L31),ISNUMBER(M31)),L31*M31,"") | P31: =IF(AND(ISNUMBER(O31),ISNUMBER(M31)),O31*M31,"") | Q31: =IF(AND(ISNUMBER(N31),ISNUMBER(P31)),N31-P31,"") | R31: =IF(AND(ISNUMBER(Q31),ISNUMBER(Parámetros!$B$2)),Q31*Parámetros!$B$2,"") | U31: =IF(COUNT(R31:T31)=0,"",SUM(R31:T31))
A32: Gestión Contable RRHH | B32: Claude Team | C32: A | D32: GC-2 | E32: Revisión por muestreo de gastos de representación y de vehículos, con conciliación de saldos; (ver programa.md) | F32: 10 | G32: F2 | N32: =IF(AND(ISNUMBER(L32),ISNUMBER(M32)),L32*M32,"") | P32: =IF(AND(ISNUMBER(O32),ISNUMBER(M32)),O32*M32,"") | Q32: =IF(AND(ISNUMBER(N32),ISNUMBER(P32)),N32-P32,"") | R32: =IF(AND(ISNUMBER(Q32),ISNUMBER(Parámetros!$B$2)),Q32*Parámetros!$B$2,"") | U32: =IF(COUNT(R32:T32)=0,"",SUM(R32:T32))
A33: Gestión Contable RRHH | B33: Claude Team | C33: A | D33: GC-3 | E33: Distribución de la factura HCM por beneficiario, plan y centro de costo, sobre la base única | F33: 10 | G33: F3 | N33: =IF(AND(ISNUMBER(L33),ISNUMBER(M33)),L33*M33,"") | P33: =IF(AND(ISNUMBER(O33),ISNUMBER(M33)),O33*M33,"") | Q33: =IF(AND(ISNUMBER(N33),ISNUMBER(P33)),N33-P33,"") | R33: =IF(AND(ISNUMBER(Q33),ISNUMBER(Parámetros!$B$2)),Q33*Parámetros!$B$2,"") | U33: =IF(COUNT(R33:T33)=0,"",SUM(R33:T33))
A34: Gestión Contable RRHH | B34: Claude Team | C34: A | D34: GC-4 | E34: Tablero de ejecución presupuestaria de Recursos Humanos | F34: 9 | G34: F3 | N34: =IF(AND(ISNUMBER(L34),ISNUMBER(M34)),L34*M34,"") | P34: =IF(AND(ISNUMBER(O34),ISNUMBER(M34)),O34*M34,"") | Q34: =IF(AND(ISNUMBER(N34),ISNUMBER(P34)),N34-P34,"") | R34: =IF(AND(ISNUMBER(Q34),ISNUMBER(Parámetros!$B$2)),Q34*Parámetros!$B$2,"") | U34: =IF(COUNT(R34:T34)=0,"",SUM(R34:T34))
A35: Gestión de Gente | B35: Claude Team | C35: B | D35: GG-1 | E35: Formulario único de ingreso que llena los formatos de cada empresa, arma el expediente y (ver programa.md) | F35: 14 | G35: F1 | N35: =IF(AND(ISNUMBER(L35),ISNUMBER(M35)),L35*M35,"") | P35: =IF(AND(ISNUMBER(O35),ISNUMBER(M35)),O35*M35,"") | Q35: =IF(AND(ISNUMBER(N35),ISNUMBER(P35)),N35-P35,"") | R35: =IF(AND(ISNUMBER(Q35),ISNUMBER(Parámetros!$B$2)),Q35*Parámetros!$B$2,"") | U35: =IF(COUNT(R35:T35)=0,"",SUM(R35:T35))
A36: Gestión de Gente | B36: Claude Team | C36: B | D36: GG-3 | E36: Filtrado de CV por vacante, resumen frente al perfil, ranking y acuse; borrador de perfil de (ver programa.md) | F36: 12 | G36: F1 | N36: =IF(AND(ISNUMBER(L36),ISNUMBER(M36)),L36*M36,"") | P36: =IF(AND(ISNUMBER(O36),ISNUMBER(M36)),O36*M36,"") | Q36: =IF(AND(ISNUMBER(N36),ISNUMBER(P36)),N36-P36,"") | R36: =IF(AND(ISNUMBER(Q36),ISNUMBER(Parámetros!$B$2)),Q36*Parámetros!$B$2,"") | U36: =IF(COUNT(R36:T36)=0,"",SUM(R36:T36))
A37: Gestión de Gente | B37: Claude Team | C37: B | D37: GG-4 | E37: Ficha de entrevista llenada desde la transcripción y ficha ejecutiva para el líder; con (ver programa.md) | F37: 10 | G37: F1 | N37: =IF(AND(ISNUMBER(L37),ISNUMBER(M37)),L37*M37,"") | P37: =IF(AND(ISNUMBER(O37),ISNUMBER(M37)),O37*M37,"") | Q37: =IF(AND(ISNUMBER(N37),ISNUMBER(P37)),N37-P37,"") | R37: =IF(AND(ISNUMBER(Q37),ISNUMBER(Parámetros!$B$2)),Q37*Parámetros!$B$2,"") | U37: =IF(COUNT(R37:T37)=0,"",SUM(R37:T37))
A38: Gestión de Gente | B38: Claude Team | C38: B | D38: GG-5 | E38: Capacitación | F38: 15 | G38: F1 | N38: =IF(AND(ISNUMBER(L38),ISNUMBER(M38)),L38*M38,"") | P38: =IF(AND(ISNUMBER(O38),ISNUMBER(M38)),O38*M38,"") | Q38: =IF(AND(ISNUMBER(N38),ISNUMBER(P38)),N38-P38,"") | R38: =IF(AND(ISNUMBER(Q38),ISNUMBER(Parámetros!$B$2)),Q38*Parámetros!$B$2,"") | U38: =IF(COUNT(R38:T38)=0,"",SUM(R38:T38))
A39: Gestión de Gente | B39: Claude Team | C39: B | D39: GG-2 | E39: Contratos desde la ficha y base de seguimiento con alertas | F39: 13 | G39: F2 | N39: =IF(AND(ISNUMBER(L39),ISNUMBER(M39)),L39*M39,"") | P39: =IF(AND(ISNUMBER(O39),ISNUMBER(M39)),O39*M39,"") | Q39: =IF(AND(ISNUMBER(N39),ISNUMBER(P39)),N39-P39,"") | R39: =IF(AND(ISNUMBER(Q39),ISNUMBER(Parámetros!$B$2)),Q39*Parámetros!$B$2,"") | U39: =IF(COUNT(R39:T39)=0,"",SUM(R39:T39))
A40: Gestión de Gente | B40: Claude Team | C40: B | D40: GG-7 | E40: Onboarding y comunicación del ingreso | F40: 14 | G40: F2 | N40: =IF(AND(ISNUMBER(L40),ISNUMBER(M40)),L40*M40,"") | P40: =IF(AND(ISNUMBER(O40),ISNUMBER(M40)),O40*M40,"") | Q40: =IF(AND(ISNUMBER(N40),ISNUMBER(P40)),N40-P40,"") | R40: =IF(AND(ISNUMBER(Q40),ISNUMBER(Parámetros!$B$2)),Q40*Parámetros!$B$2,"") | U40: =IF(COUNT(R40:T40)=0,"",SUM(R40:T40))
...

Sheet Resumen por área
A1: Área | B1: Soluciones | C1: Horas actuales al mes | D1: Horas con la solución al mes | E1: Horas recuperadas al mes | F1: Valor de las horas (USD/mes) | G1: Retrabajo y errores (USD/mes) | H1: Pagos o cobros tardíos (USD/mes) | I1: Retorno mensual (USD) | J1: Retorno anual (USD) | K1: Posiciones equivalentes a las horas recuperadas | L1: Meta a 30 días (h/mes) | M1: Meta a 60 días | N1: Meta a 90 días
A2: Contabilidad y Cuentas por Pagar | B2: =COUNTIFS('Retorno por proceso'!$A$2:$A$45,$A2) | C2: =SUMIFS('Retorno por proceso'!$N$2:$N$45,'Retorno por proceso'!$A$2:$A$45,$A2) | D2: =SUMIFS('Retorno por proceso'!$P$2:$P$45,'Retorno por proceso'!$A$2:$A$45,$A2) | E2: =SUMIFS('Retorno por proceso'!$Q$2:$Q$45,'Retorno por proceso'!$A$2:$A$45,$A2) | F2: =SUMIFS('Retorno por proceso'!$R$2:$R$45,'Retorno por proceso'!$A$2:$A$45,$A2) | G2: =SUMIFS('Retorno por proceso'!$S$2:$S$45,'Retorno por proceso'!$A$2:$A$45,$A2) | H2: =SUMIFS('Retorno por proceso'!$T$2:$T$45,'Retorno por proceso'!$A$2:$A$45,$A2) | I2: =SUMIFS('Retorno por proceso'!$U$2:$U$45,'Retorno por proceso'!$A$2:$A$45,$A2) | J2: =IF(I2=0,"",I2*12) | K2: =IF(AND(ISNUMBER(E2),ISNUMBER(Parámetros!$B$3),Parámetros!$B$3>0),E2/Parámetros!$B$3,"") | L2: =SUMIFS('Retorno por proceso'!$W$2:$W$45,'Retorno por proceso'!$A$2:$A$45,$A2) | M2: =SUMIFS('Retorno por proceso'!$X$2:$X$45,'Retorno por proceso'!$A$2:$A$45,$A2) | N2: =SUMIFS('Retorno por proceso'!$Y$2:$Y$45,'Retorno por proceso'!$A$2:$A$45,$A2)
A3: Tesorería | B3: =COUNTIFS('Retorno por proceso'!$A$2:$A$45,$A3) | C3: =SUMIFS('Retorno por proceso'!$N$2:$N$45,'Retorno por proceso'!$A$2:$A$45,$A3) | D3: =SUMIFS('Retorno por proceso'!$P$2:$P$45,'Retorno por proceso'!$A$2:$A$45,$A3) | E3: =SUMIFS('Retorno por proceso'!$Q$2:$Q$45,'Retorno por proceso'!$A$2:$A$45,$A3) | F3: =SUMIFS('Retorno por proceso'!$R$2:$R$45,'Retorno por proceso'!$A$2:$A$45,$A3) | G3: =SUMIFS('Retorno por proceso'!$S$2:$S$45,'Retorno por proceso'!$A$2:$A$45,$A3) | H3: =SUMIFS('Retorno por proceso'!$T$2:$T$45,'Retorno por proceso'!$A$2:$A$45,$A3) | I3: =SUMIFS('Retorno por proceso'!$U$2:$U$45,'Retorno por proceso'!$A$2:$A$45,$A3) | J3: =IF(I3=0,"",I3*12) | K3: =IF(AND(ISNUMBER(E3),ISNUMBER(Parámetros!$B$3),Parámetros!$B$3>0),E3/Parámetros!$B$3,"") | L3: =SUMIFS('Retorno por proceso'!$W$2:$W$45,'Retorno por proceso'!$A$2:$A$45,$A3) | M3: =SUMIFS('Retorno por proceso'!$X$2:$X$45,'Retorno por proceso'!$A$2:$A$45,$A3) | N3: =SUMIFS('Retorno por proceso'!$Y$2:$Y$45,'Retorno por proceso'!$A$2:$A$45,$A3)
A4: Cuentas por Cobrar | B4: =COUNTIFS('Retorno por proceso'!$A$2:$A$45,$A4) | C4: =SUMIFS('Retorno por proceso'!$N$2:$N$45,'Retorno por proceso'!$A$2:$A$45,$A4) | D4: =SUMIFS('Retorno por proceso'!$P$2:$P$45,'Retorno por proceso'!$A$2:$A$45,$A4) | E4: =SUMIFS('Retorno por proceso'!$Q$2:$Q$45,'Retorno por proceso'!$A$2:$A$45,$A4) | F4: =SUMIFS('Retorno por proceso'!$R$2:$R$45,'Retorno por proceso'!$A$2:$A$45,$A4) | G4: =SUMIFS('Retorno por proceso'!$S$2:$S$45,'Retorno por proceso'!$A$2:$A$45,$A4) | H4: =SUMIFS('Retorno por proceso'!$T$2:$T$45,'Retorno por proceso'!$A$2:$A$45,$A4) | I4: =SUMIFS('Retorno por proceso'!$U$2:$U$45,'Retorno por proceso'!$A$2:$A$45,$A4) | J4: =IF(I4=0,"",I4*12) | K4: =IF(AND(ISNUMBER(E4),ISNUMBER(Parámetros!$B$3),Parámetros!$B$3>0),E4/Parámetros!$B$3,"") | L4: =SUMIFS('Retorno por proceso'!$W$2:$W$45,'Retorno por proceso'!$A$2:$A$45,$A4) | M4: =SUMIFS('Retorno por proceso'!$X$2:$X$45,'Retorno por proceso'!$A$2:$A$45,$A4) | N4: =SUMIFS('Retorno por proceso'!$Y$2:$Y$45,'Retorno por proceso'!$A$2:$A$45,$A4)
A5: Finanzas | B5: =COUNTIFS('Retorno por proceso'!$A$2:$A$45,$A5) | C5: =SUMIFS('Retorno por proceso'!$N$2:$N$45,'Retorno por proceso'!$A$2:$A$45,$A5) | D5: =SUMIFS('Retorno por proceso'!$P$2:$P$45,'Retorno por proceso'!$A$2:$A$45,$A5) | E5: =SUMIFS('Retorno por proceso'!$Q$2:$Q$45,'Retorno por proceso'!$A$2:$A$45,$A5) | F5: =SUMIFS('Retorno por proceso'!$R$2:$R$45,'Retorno por proceso'!$A$2:$A$45,$A5) | G5: =SUMIFS('Retorno por proceso'!$S$2:$S$45,'Retorno por proceso'!$A$2:$A$45,$A5) | H5: =SUMIFS('Retorno por proceso'!$T$2:$T$45,'Retorno por proceso'!$A$2:$A$45,$A5) | I5: =SUMIFS('Retorno por proceso'!$U$2:$U$45,'Retorno por proceso'!$A$2:$A$45,$A5) | J5: =IF(I5=0,"",I5*12) | K5: =IF(AND(ISNUMBER(E5),ISNUMBER(Parámetros!$B$3),Parámetros!$B$3>0),E5/Parámetros!$B$3,"") | L5: =SUMIFS('Retorno por proceso'!$W$2:$W$45,'Retorno por proceso'!$A$2:$A$45,$A5) | M5: =SUMIFS('Retorno por proceso'!$X$2:$X$45,'Retorno por proceso'!$A$2:$A$45,$A5) | N5: =SUMIFS('Retorno por proceso'!$Y$2:$Y$45,'Retorno por proceso'!$A$2:$A$45,$A5)
A6: Comercial Región Centro-Sur | B6: =COUNTIFS('Retorno por proceso'!$A$2:$A$45,$A6) | C6: =SUMIFS('Retorno por proceso'!$N$2:$N$45,'Retorno por proceso'!$A$2:$A$45,$A6) | D6: =SUMIFS('Retorno por proceso'!$P$2:$P$45,'Retorno por proceso'!$A$2:$A$45,$A6) | E6: =SUMIFS('Retorno por proceso'!$Q$2:$Q$45,'Retorno por proceso'!$A$2:$A$45,$A6) | F6: =SUMIFS('Retorno por proceso'!$R$2:$R$45,'Retorno por proceso'!$A$2:$A$45,$A6) | G6: =SUMIFS('Retorno por proceso'!$S$2:$S$45,'Retorno por proceso'!$A$2:$A$45,$A6) | H6: =SUMIFS('Retorno por proceso'!$T$2:$T$45,'Retorno por proceso'!$A$2:$A$45,$A6) | I6: =SUMIFS('Retorno por proceso'!$U$2:$U$45,'Retorno por proceso'!$A$2:$A$45,$A6) | J6: =IF(I6=0,"",I6*12) | K6: =IF(AND(ISNUMBER(E6),ISNUMBER(Parámetros!$B$3),Parámetros!$B$3>0),E6/Parámetros!$B$3,"") | L6: =SUMIFS('Retorno por proceso'!$W$2:$W$45,'Retorno por proceso'!$A$2:$A$45,$A6) | M6: =SUMIFS('Retorno por proceso'!$X$2:$X$45,'Retorno por proceso'!$A$2:$A$45,$A6) | N6: =SUMIFS('Retorno por proceso'!$Y$2:$Y$45,'Retorno por proceso'!$A$2:$A$45,$A6)
A7: Base de datos de empleados (proceso base) | B7: =COUNTIFS('Retorno por proceso'!$A$2:$A$45,$A7) | C7: =SUMIFS('Retorno por proceso'!$N$2:$N$45,'Retorno por proceso'!$A$2:$A$45,$A7) | D7: =SUMIFS('Retorno por proceso'!$P$2:$P$45,'Retorno por proceso'!$A$2:$A$45,$A7) | E7: =SUMIFS('Retorno por proceso'!$Q$2:$Q$45,'Retorno por proceso'!$A$2:$A$45,$A7) | F7: =SUMIFS('Retorno por proceso'!$R$2:$R$45,'Retorno por proceso'!$A$2:$A$45,$A7) | G7: =SUMIFS('Retorno por proceso'!$S$2:$S$45,'Retorno por proceso'!$A$2:$A$45,$A7) | H7: =SUMIFS('Retorno por proceso'!$T$2:$T$45,'Retorno por proceso'!$A$2:$A$45,$A7) | I7: =SUMIFS('Retorno por proceso'!$U$2:$U$45,'Retorno por proceso'!$A$2:$A$45,$A7) | J7: =IF(I7=0,"",I7*12) | K7: =IF(AND(ISNUMBER(E7),ISNUMBER(Parámetros!$B$3),Parámetros!$B$3>0),E7/Parámetros!$B$3,"") | L7: =SUMIFS('Retorno por proceso'!$W$2:$W$45,'Retorno por proceso'!$A$2:$A$45,$A7) | M7: =SUMIFS('Retorno por proceso'!$X$2:$X$45,'Retorno por proceso'!$A$2:$A$45,$A7) | N7: =SUMIFS('Retorno por proceso'!$Y$2:$Y$45,'Retorno por proceso'!$A$2:$A$45,$A7)
A8: Nómina | B8: =COUNTIFS('Retorno por proceso'!$A$2:$A$45,$A8) | C8: =SUMIFS('Retorno por proceso'!$N$2:$N$45,'Retorno por proceso'!$A$2:$A$45,$A8) | D8: =SUMIFS('Retorno por proceso'!$P$2:$P$45,'Retorno por proceso'!$A$2:$A$45,$A8) | E8: =SUMIFS('Retorno por proceso'!$Q$2:$Q$45,'Retorno por proceso'!$A$2:$A$45,$A8) | F8: =SUMIFS('Retorno por proceso'!$R$2:$R$45,'Retorno por proceso'!$A$2:$A$45,$A8) | G8: =SUMIFS('Retorno por proceso'!$S$2:$S$45,'Retorno por proceso'!$A$2:$A$45,$A8) | H8: =SUMIFS('Retorno por proceso'!$T$2:$T$45,'Retorno por proceso'!$A$2:$A$45,$A8) | I8: =SUMIFS('Retorno por proceso'!$U$2:$U$45,'Retorno por proceso'!$A$2:$A$45,$A8) | J8: =IF(I8=0,"",I8*12) | K8: =IF(AND(ISNUMBER(E8),ISNUMBER(Parámetros!$B$3),Parámetros!$B$3>0),E8/Parámetros!$B$3,"") | L8: =SUMIFS('Retorno por proceso'!$W$2:$W$45,'Retorno por proceso'!$A$2:$A$45,$A8) | M8: =SUMIFS('Retorno por proceso'!$X$2:$X$45,'Retorno por proceso'!$A$2:$A$45,$A8) | N8: =SUMIFS('Retorno por proceso'!$Y$2:$Y$45,'Retorno por proceso'!$A$2:$A$45,$A8)
A9: Servicio Médico | B9: =COUNTIFS('Retorno por proceso'!$A$2:$A$45,$A9) | C9: =SUMIFS('Retorno por proceso'!$N$2:$N$45,'Retorno por proceso'!$A$2:$A$45,$A9) | D9: =SUMIFS('Retorno por proceso'!$P$2:$P$45,'Retorno por proceso'!$A$2:$A$45,$A9) | E9: =SUMIFS('Retorno por proceso'!$Q$2:$Q$45,'Retorno por proceso'!$A$2:$A$45,$A9) | F9: =SUMIFS('Retorno por proceso'!$R$2:$R$45,'Retorno por proceso'!$A$2:$A$45,$A9) | G9: =SUMIFS('Retorno por proceso'!$S$2:$S$45,'Retorno por proceso'!$A$2:$A$45,$A9) | H9: =SUMIFS('Retorno por proceso'!$T$2:$T$45,'Retorno por proceso'!$A$2:$A$45,$A9) | I9: =SUMIFS('Retorno por proceso'!$U$2:$U$45,'Retorno por proceso'!$A$2:$A$45,$A9) | J9: =IF(I9=0,"",I9*12) | K9: =IF(AND(ISNUMBER(E9),ISNUMBER(Parámetros!$B$3),Parámetros!$B$3>0),E9/Parámetros!$B$3,"") | L9: =SUMIFS('Retorno por proceso'!$W$2:$W$45,'Retorno por proceso'!$A$2:$A$45,$A9) | M9: =SUMIFS('Retorno por proceso'!$X$2:$X$45,'Retorno por proceso'!$A$2:$A$45,$A9) | N9: =SUMIFS('Retorno por proceso'!$Y$2:$Y$45,'Retorno por proceso'!$A$2:$A$45,$A9)
A10: Gestión Contable RRHH | B10: =COUNTIFS('Retorno por proceso'!$A$2:$A$45,$A10) | C10: =SUMIFS('Retorno por proceso'!$N$2:$N$45,'Retorno por proceso'!$A$2:$A$45,$A10) | D10: =SUMIFS('Retorno por proceso'!$P$2:$P$45,'Retorno por proceso'!$A$2:$A$45,$A10) | E10: =SUMIFS('Retorno por proceso'!$Q$2:$Q$45,'Retorno por proceso'!$A$2:$A$45,$A10) | F10: =SUMIFS('Retorno por proceso'!$R$2:$R$45,'Retorno por proceso'!$A$2:$A$45,$A10) | G10: =SUMIFS('Retorno por proceso'!$S$2:$S$45,'Retorno por proceso'!$A$2:$A$45,$A10) | H10: =SUMIFS('Retorno por proceso'!$T$2:$T$45,'Retorno por proceso'!$A$2:$A$45,$A10) | I10: =SUMIFS('Retorno por proceso'!$U$2:$U$45,'Retorno por proceso'!$A$2:$A$45,$A10) | J10: =IF(I10=0,"",I10*12) | K10: =IF(AND(ISNUMBER(E10),ISNUMBER(Parámetros!$B$3),Parámetros!$B$3>0),E10/Parámetros!$B$3,"") | L10: =SUMIFS('Retorno por proceso'!$W$2:$W$45,'Retorno por proceso'!$A$2:$A$45,$A10) | M10: =SUMIFS('Retorno por proceso'!$X$2:$X$45,'Retorno por proceso'!$A$2:$A$45,$A10) | N10: =SUMIFS('Retorno por proceso'!$Y$2:$Y$45,'Retorno por proceso'!$A$2:$A$45,$A10)
A11: Gestión de Gente | B11: =COUNTIFS('Retorno por proceso'!$A$2:$A$45,$A11) | C11: =SUMIFS('Retorno por proceso'!$N$2:$N$45,'Retorno por proceso'!$A$2:$A$45,$A11) | D11: =SUMIFS('Retorno por proceso'!$P$2:$P$45,'Retorno por proceso'!$A$2:$A$45,$A11) | E11: =SUMIFS('Retorno por proceso'!$Q$2:$Q$45,'Retorno por proceso'!$A$2:$A$45,$A11) | F11: =SUMIFS('Retorno por proceso'!$R$2:$R$45,'Retorno por proceso'!$A$2:$A$45,$A11) | G11: =SUMIFS('Retorno por proceso'!$S$2:$S$45,'Retorno por proceso'!$A$2:$A$45,$A11) | H11: =SUMIFS('Retorno por proceso'!$T$2:$T$45,'Retorno por proceso'!$A$2:$A$45,$A11) | I11: =SUMIFS('Retorno por proceso'!$U$2:$U$45,'Retorno por proceso'!$A$2:$A$45,$A11) | J11: =IF(I11=0,"",I11*12) | K11: =IF(AND(ISNUMBER(E11),ISNUMBER(Parámetros!$B$3),Parámetros!$B$3>0),E11/Parámetros!$B$3,"") | L11: =SUMIFS('Retorno por proceso'!$W$2:$W$45,'Retorno por proceso'!$A$2:$A$45,$A11) | M11: =SUMIFS('Retorno por proceso'!$X$2:$X$45,'Retorno por proceso'!$A$2:$A$45,$A11) | N11: =SUMIFS('Retorno por proceso'!$Y$2:$Y$45,'Retorno por proceso'!$A$2:$A$45,$A11)
A12: Beneficios y Recepción | B12: =COUNTIFS('Retorno por proceso'!$A$2:$A$45,$A12) | C12: =SUMIFS('Retorno por proceso'!$N$2:$N$45,'Retorno por proceso'!$A$2:$A$45,$A12) | D12: =SUMIFS('Retorno por proceso'!$P$2:$P$45,'Retorno por proceso'!$A$2:$A$45,$A12) | E12: =SUMIFS('Retorno por proceso'!$Q$2:$Q$45,'Retorno por proceso'!$A$2:$A$45,$A12) | F12: =SUMIFS('Retorno por proceso'!$R$2:$R$45,'Retorno por proceso'!$A$2:$A$45,$A12) | G12: =SUMIFS('Retorno por proceso'!$S$2:$S$45,'Retorno por proceso'!$A$2:$A$45,$A12) | H12: =SUMIFS('Retorno por proceso'!$T$2:$T$45,'Retorno por proceso'!$A$2:$A$45,$A12) | I12: =SUMIFS('Retorno por proceso'!$U$2:$U$45,'Retorno por proceso'!$A$2:$A$45,$A12) | J12: =IF(I12=0,"",I12*12) | K12: =IF(AND(ISNUMBER(E12),ISNUMBER(Parámetros!$B$3),Parámetros!$B$3>0),E12/Parámetros!$B$3,"") | L12: =SUMIFS('Retorno por proceso'!$W$2:$W$45,'Retorno por proceso'!$A$2:$A$45,$A12) | M12: =SUMIFS('Retorno por proceso'!$X$2:$X$45,'Retorno por proceso'!$A$2:$A$45,$A12) | N12: =SUMIFS('Retorno por proceso'!$Y$2:$Y$45,'Retorno por proceso'!$A$2:$A$45,$A12)
A14: TOTAL | B14: =SUM(B2:B12) | C14: =SUM(C2:C12) | D14: =SUM(D2:D12) | E14: =SUM(E2:E12) | F14: =SUM(F2:F12) | G14: =SUM(G2:G12) | H14: =SUM(H2:H12) | I14: =SUM(I2:I12) | ... N14: =SUM(N2:N12)

Sheet Dotación y nómina
A1: Área | B1: Personas hoy en el área | C1: Equivalencia: personas que haría falta para procesar la data a mano | D1: Fuente de la equivalencia | E1: Posiciones que representa hoy el trabajo manual | F1: Posiciones que se reducen con las soluciones | G1: Posiciones que no hará falta contratar | H1: Costo anual por posición (escala salarial de DUSA, USD) | I1: Costo anual de las posiciones reducidas (USD) | J1: Costo anual de las contrataciones evitadas (USD) | K1: Total anual (USD) | L1: Tipo de dato | M1: Observación
A2: Contabilidad y Cuentas por Pagar | B2: 6 | I2: =IF(AND(ISNUMBER(F2),ISNUMBER(H2)),F2*H2,"") | J2: =IF(AND(ISNUMBER(G2),ISNUMBER(H2)),G2*H2,"") | K2: =IF(COUNT(I2:J2)=0,"",SUM(I2:J2)) | M2: 6 personas ejecutan los procesos (Informe de Detección, recogido en dusa-cai012/brief.md)
A3: Tesorería | B3: 2 | I3: =IF(AND(ISNUMBER(F3),ISNUMBER(H3)),F3*H3,"") | J3: =IF(AND(ISNUMBER(G3),ISNUMBER(H3)),G3*H3,"") | K3: =IF(COUNT(I3:J3)=0,"",SUM(I3:J3)) | M3: 2 personas donde antes había 5 (Informe Final de Auditoría IA, 04/09/2026). Ya hubo una reducción previa: tratar con cuidado
A4: Cuentas por Cobrar | B4: 4 | C4: 8 | D4: La líder estimó que procesar la data a mano requeriría unas 8 personas (mensaje de revisión del 05/10/2026); verificar contra la ficha | I4: =IF(AND(ISNUMBER(F4),ISNUMBER(H4)),F4*H4,"") | J4: =IF(AND(ISNUMBER(G4),ISNUMBER(H4)),G4*H4,"") | K4: =IF(COUNT(I4:J4)=0,"",SUM(I4:J4)) | M4: 4 personas ejecutan los procesos hoy
A5: Finanzas | B5: 2 | I5: =IF(AND(ISNUMBER(F5),ISNUMBER(H5)),F5*H5,"") | J5: =IF(AND(ISNUMBER(G5),ISNUMBER(H5)),G5*H5,"") | K5: =IF(COUNT(I5:J5)=0,"",SUM(I5:J5)) | M5: 2 personas ejecutan los procesos (Informe de Detección)
A6: Comercial Región Centro-Sur | I6: =IF(AND(ISNUMBER(F6),ISNUMBER(H6)),F6*H6,"") | J6: =IF(AND(ISNUMBER(G6),ISNUMBER(H6)),G6*H6,"") | K6: =IF(COUNT(I6:J6)=0,"",SUM(I6:J6)) | M6: El informe cita 9 personas en Comercial (incluye Región Caracas, fuera de esta propuesta): separar la dotación de Centro-Sur
A7: Base de datos de empleados (proceso base) | I7: =IF(AND(ISNUMBER(F7),ISNUMBER(H7)),F7*H7,"") | J7: =IF(AND(ISNUMBER(G7),ISNUMBER(H7)),G7*H7,"") | K7: =IF(COUNT(I7:J7)=0,"",SUM(I7:J7)) | M7: Proceso base de Recursos Humanos
A8: Nómina | B8: 3 | I8: =IF(AND(ISNUMBER(F8),ISNUMBER(H8)),F8*H8,"") | J8: =IF(AND(ISNUMBER(G8),ISNUMBER(H8)),G8*H8,"") | K8: =IF(COUNT(I8:J8)=0,"",SUM(I8:J8)) | M8: 3 personas, incluido el líder (ficha de Nómina, 01/10/2026)
A9: Servicio Médico | B9: 3 | I9: =IF(AND(ISNUMBER(F9),ISNUMBER(H9)),F9*H9,"") | J9: =IF(AND(ISNUMBER(G9),ISNUMBER(H9)),G9*H9,"") | K9: =IF(COUNT(I9:J9)=0,"",SUM(I9:J9)) | M9: 3 personas fijas; eran 12 antes de una reducción de personal (ficha de Servicio Médico). Ya hubo una reducción previa: tratar con cuidado
A10: Gestión Contable RRHH | I10: =IF(AND(ISNUMBER(F10),ISNUMBER(H10)),F10*H10,"") | J10: =IF(AND(ISNUMBER(G10),ISNUMBER(H10)),G10*H10,"") | K10: =IF(COUNT(I10:J10)=0,"",SUM(I10:J10))
A11: Gestión de Gente | I11: =IF(AND(ISNUMBER(F11),ISNUMBER(H11)),F11*H11,"") | J11: =IF(AND(ISNUMBER(G11),ISNUMBER(H11)),G11*H11,"") | K11: =IF(COUNT(I11:J11)=0,"",SUM(I11:J11)) | M11: Talento Humano completo: ~15 personas en 5 sub-áreas (CAP-087/088)
A12: Beneficios y Recepción | I12: =IF(AND(ISNUMBER(F12),ISNUMBER(H12)),F12*H12,"") | J12: =IF(AND(ISNUMBER(G12),ISNUMBER(H12)),G12*H12,"") | K12: =IF(COUNT(I12:J12)=0,"",SUM(I12:J12))
A14: TOTAL | E14: =SUM(E2:E12) | F14: =SUM(F2:F12) | G14: =SUM(G2:G12) | I14: =SUM(I2:I12) | J14: =SUM(J2:J12) | K14: =SUM(K2:K12)

Sheet Sistemas
A1: Desarrollo de Sistemas de DUSA | B1: Qué atiende | C1: Área | D1: Volumen mensual | E1: Estado declarado | F1: Fecha registrada | G1: Horas que seguirán manuales mientras no llegue (al mes) | H1: Fuente
A2: Desarrollo interno de recepción y carga de órdenes de compra | B2: Lectura de facturas escaneadas y preregistro en JD Edwards | C2: Contabilidad y CxP | D2: Más de 300 facturas al mes | E2: Más de 300 facturas al mes siguen digitándose hasta su entrega | F2: Sin fecha de entrega registrada | H2: DUSA_Habilidades_Procesos_Ruta_y_Horas_6.docx, «Lo que asume Sistemas de DUSA» (mesa del 02/10/2026)
A3: Aplicación de reporte de gasto | B3: Validación fiscal de la factura y alerta de proveedor no creado | C3: Contabilidad y CxP | E3: Falta construir el preregistro de proveedor | F3: Sin fecha de entrega registrada | H3: DUSA_Habilidades_Procesos_Ruta_y_Horas_6.docx, «Lo que asume Sistemas de DUSA» (mesa del 02/10/2026)
A4: Tesote: extracción por API tres veces al día, más la herramienta de tesorería | B4: Validación de movimientos bancarios y alerta de descuadre | C4: Tesorería | D4: Cerca de 5.000 movimientos al mes (Informe de Auditoría IA, 04/09/2026) | E4: La revisión del extracto sigue siendo humana | F4: Contrato en redacción (confirmar si hay fecha de entrega) | H4: DUSA_Habilidades_Procesos_Ruta_y_Horas_6.docx, «Lo que asume Sistemas de DUSA» (mesa del 02/10/2026)
A5: Tesote: disponibilidad consolidada por banco | B5: Disponibilidad bancaria neta | C5: Tesorería | E5: — | F5: Contrato en redacción (confirmar si hay fecha de entrega) | H5: DUSA_Habilidades_Procesos_Ruta_y_Horas_6.docx, «Lo que asume Sistemas de DUSA» (mesa del 02/10/2026)
A6: Herramienta de tesorería existente | B6: Flujo de caja proyectado contra real | C6: Tesorería | E6: — | F6: Sin fecha de entrega registrada | H6: DUSA_Habilidades_Procesos_Ruta_y_Horas_6.docx, «Lo que asume Sistemas de DUSA» (mesa del 02/10/2026)
A7: Portal de autopago y Bitácora de cobranza | B7: Sinceración de cartera y explicación de saldos abiertos | C7: Cuentas por Cobrar | E7: La cartera debe quedar sincerada antes de que el portal muestre saldos al cliente | F7: Sin fecha de entrega registrada | H7: DUSA_Habilidades_Procesos_Ruta_y_Horas_6.docx, «Lo que asume Sistemas de DUSA» (mesa del 02/10/2026)
A8: Portal de autopago | B8: Imputación de pagos por código cuenta cliente | C8: Cuentas por Cobrar | E8: — | F8: Sin fecha de entrega registrada | H8: DUSA_Habilidades_Procesos_Ruta_y_Horas_6.docx, «Lo que asume Sistemas de DUSA» (mesa del 02/10/2026)
A9: Portal de autopago | B9: Descuento financiero según política y fecha de emisión | C9: Cuentas por Cobrar | E9: — | F9: Sin fecha de entrega registrada | H9: DUSA_Habilidades_Procesos_Ruta_y_Horas_6.docx, «Lo que asume Sistemas de DUSA» (mesa del 02/10/2026)
A10: Fase 2 del autopago | B10: Descuentos comerciales del pedido al cobro (solución definitiva) | C10: Cuentas por Cobrar | E10: Sin fecha; Intezia cubre el intervalo con CC-1 | F10: Sin fecha de entrega registrada | H10: DUSA_Habilidades_Procesos_Ruta_y_Horas_6.docx, «Lo que asume Sistemas de DUSA» (mesa del 02/10/2026)
A11: Bitácora, autopago y Tesote | B11: Recordatorios de cobranza y falso estatus de mora | C11: Comercial Centro-Sur | E11: — | F11: Sin fecha de entrega registrada | H11: DUSA_Habilidades_Procesos_Ruta_y_Horas_6.docx, «Lo que asume Sistemas de DUSA» (mesa del 02/10/2026)
A12: Autopago, Bitácora y pago directo | B12: Trazabilidad de abonos, copia de factura, calculadora y método único de abonos | C12: Comercial Región Caracas | E12: El autopago supone un cliente que se autogestiona; la cartera de Caracas es corporativa | F12: Sin fecha de entrega registrada | H12: DUSA_Habilidades_Procesos_Ruta_y_Horas_6.docx, «Lo que asume Sistemas de DUSA» (mesa del 02/10/2026)
A13: Portal único de peticiones (Sistemas decide si lo construye con Intezia o adapta la intranet) | B13: Taxis, boletos, hoteles, salas, transporte, seguros de viaje, comidas, valija y copias de certificados | C13: Beneficios y Recepción | E13: El sistema de taxis actual casi no se usa: exige VPN y no funciona desde el teléfono | F13: Sin fecha de entrega registrada | H13: DUSA_Habilidades_Procesos_Ruta_y_Horas_6.docx, «Lo que asume Sistemas de DUSA» (mesa del 02/10/2026)
A14: Aplicativo de inventario de Sistemas, montado en julio | B14: Inventario de licores y uniformes | C14: Beneficios y Recepción | E14: Sin uso ni capacitación | F14: Sin fecha de entrega registrada | H14: DUSA_Habilidades_Procesos_Ruta_y_Horas_6.docx, «Lo que asume Sistemas de DUSA» (mesa del 02/10/2026)
A15: Autogestión en la intranet | B15: Actualización de carga familiar por el trabajador y registro del plan vacacional | C15: Beneficios y Administración de personal | E15: Requiere aceptación del sindicato | F15: Sin fecha de entrega registrada | H15: DUSA_Habilidades_Procesos_Ruta_y_Horas_6.docx, «Lo que asume Sistemas de DUSA» (mesa del 02/10/2026)
A16: Intranet o módulo de SPI, por decidir | B16: Plataforma de la base única, criterio de correlativo y carga masiva | C16: Nómina y Servicio Médico | D16: Base de ≈2.200 trabajadores (Nómina) y 2.516 personas (Servicio Médico) | E16: Intezia entrega el archivo conciliado (RH-0) | F16: Sin fecha de entrega registrada | H16: DUSA_Habilidades_Procesos_Ruta_y_Horas_6.docx, «Lo que asume Sistemas de DUSA» (mesa del 02/10/2026)
A17: Sistema Médico Integral, por ticket del 01/10 | B17: Adjuntos en afiliación y carga masiva del despacho crónico | C17: Servicio Médico | D17: 1.471 medicamentos en el pedido mensual | E17: Lo complejo pasa a un tercero con costo | F17: Sin fecha de entrega registrada | H17: DUSA_Habilidades_Procesos_Ruta_y_Horas_6.docx, «Lo que asume Sistemas de DUSA» (mesa del 02/10/2026)
A18: Flujo de aprobación de Sistemas | B18: Circuito digital de solicitud y movimiento de personal | C18: Gestión de Gente y Nómina | E18: — | F18: Sin fecha de entrega registrada | H18: DUSA_Habilidades_Procesos_Ruta_y_Horas_6.docx, «Lo que asume Sistemas de DUSA» (mesa del 02/10/2026)
A19: Intranet | B19: Altas de usuario por notificación | C19: Gestión de Gente | E19: — | F19: Sin fecha de entrega registrada | H19: DUSA_Habilidades_Procesos_Ruta_y_Horas_6.docx, «Lo que asume Sistemas de DUSA» (mesa del 02/10/2026)
A20: Aplicativo, por decidir | B20: Portal de carga de facturas por el proveedor | C20: Gestión Contable RRHH | E20: — | F20: Sin fecha de entrega registrada | H20: DUSA_Habilidades_Procesos_Ruta_y_Horas_6.docx, «Lo que asume Sistemas de DUSA» (mesa del 02/10/2026)
A21: Intranet (desarrollo interno, tres años en curso) | B21: Recibos, constancias y saldos de fideicomiso para el trabajador | C21: Nómina | E21: Faltan los saldos, abonos y retiros de fideicomiso (ficha de Nómina) | F21: Sin fecha de entrega registrada | H21: DUSA_Habilidades_Procesos_Ruta_y_Horas_6.docx, «Lo que asume Sistemas de DUSA» (mesa del 02/10/2026)
A23: Nota: el insumo dice que ninguno de estos desarrollos tiene fecha de entrega registrada, salvo Tesote (contrato en redacción). Las columnas azules faltan y se completan con Sistemas. Redacción sugerida: solo hechos y números, sin juicios; Sistemas es garante del proyecto y parte del comité.

Sheet Datos disponibles
A1: Área | B1: Dato | C1: Valor | D1: Fuente | E1: Observación
A2: Nómina | B2: Personas en el equipo (incluido el líder) | C2: 3 | D2: Ficha de Nómina, 01/10/2026
A3: Nómina | B3: Trabajadores en la base de nómina | C3: ≈2.200 | D3: Ficha de Nómina, 01/10/2026
A4: Nómina | B4: Empresas con aportes parafiscales cada mes | C4: 10 a 15 | D4: Ficha de Nómina, 01/10/2026 | E4: Cuatro servicios: Seguro Social, FAOV, INCES, sindicato y pensiones
A5: Nómina | B5: Plazo para tramitar los aportes del mes | C5: 5 días hábiles | D5: Ficha de Nómina, 01/10/2026
A6: Nómina | B6: Facturas de Humaniz al mes | C6: 4 | D6: Ficha de Nómina, 01/10/2026
A7: Nómina | B7: Horas por ejecución y volumen mensual de los 8 procesos | C7: No declarado | D7: Ficha de Nómina, 01/10/2026 | E7: «Ninguna estimación de ahorro es defendible» antes de la descripción paso a paso
A8: Parafiscales | B8: Seguro Social, agosto 2026: total de cargos actuales | C8: 30.739,15 | D8: Ficha del agente de parafiscales, prueba con archivos reales | E8: Sin moneda indicada. Aportes 29.586,60 + intereses de mora 1.152,55
A9: Parafiscales | B9: Seguro Social, agosto 2026: totales anteriores no pagados | C9: 23.751,77 | D9: Ficha del agente de parafiscales | E9: Sin moneda indicada. Es el monto pendiente que detectó el agente. Total con pendientes: 54.490,92
A10: Parafiscales | B10: FAOV, agosto 2026 | C10: 2.359.683,68 | D10: Ficha del agente de parafiscales | E10: Sin moneda indicada. Planilla vencida el 14/09/2026 (alerta de mora). TXT: 358 líneas por 78.656.122,69
A11: Parafiscales | B11: INCES, segundo trimestre | C11: 2.565.115,91 | D11: Ficha del agente de parafiscales | E11: Sin moneda indicada. Retención INCES 0,5 % de DUSA: 311.920,84
A12: Parafiscales | B12: Pensiones 2038, 2074 y 2680: diferencia entre el TXT y el reporte | C12: 271.430,84 / 135.715,42 / 71.849,34 | D12: Ficha del agente de parafiscales | E12: Sin moneda indicada. El agente reporta la diferencia y no elige monto
A13: Servicio Médico | B13: Personas fijas en el área | C13: 3 (eran 12) | D13: Ficha de Servicio Médico, 01-02/10/2026 | E13: Hubo una reducción previa de personal
A14: Servicio Médico | B14: Personas en la base de beneficiarios | C14: 2.516 | D14: Ficha de Servicio Médico
A15: Servicio Médico | B15: Medicamentos en el pedido mensual de tratamiento crónico | C15: 1.471 | D15: Ficha de Servicio Médico
A16: Servicio Médico | B16: Análisis de morbilidad, mensual (manual) | C16: Casi una jornada por ejecución | D16: Ficha de Servicio Médico | E16: Los 10 minutos del agente no incluyen insumos ni revisión: no es ahorro neto
A17: Servicio Médico | B17: Informe de certificados de salud (a requerimiento, manual) | C17: Unos 3 días por informe | D17: Ficha de Servicio Médico | E17: Frecuencia no declarada
A18: Tesorería | B18: Cuentas bancarias / empresas / movimientos al mes | C18: 130 / 15 / ≈5.000 | D18: Informe Final de Auditoría IA, 04/09/2026 (dusa-cai012/brief.md) | E18: Dos personas donde antes había cinco; la mitad de la jornada en extractos
A19: Contabilidad y CxP | B19: Facturas registradas a mano al mes | C19: Más de 300 | D19: Informe Final de Auditoría IA, 04/09/2026 | E19: Ese registro lo cubre Sistemas, fuera de esta propuesta
A20: 5 áreas financiero-comerciales | B20: Personas que ejecutan los procesos | C20: 23: 6 CxP, 9 Comercial, 4 CxC, 2 Tesorería, 2 Finanzas | D20: Informe de Detección (dusa-cai012/brief.md)
A21: Cuentas por Cobrar | B21: Equivalencia en personas para procesar la data a mano | C21: ≈8 | D21: Mensaje de revisión del 05/10/2026 (estimación de la líder) | E21: Verificar contra la ficha de Cuentas por Cobrar
A22: Recursos Humanos | B22: Compañías con ficha numerada por separado / fuentes del mismo trabajador | C22: 18 / 5 | D22: Informe de Detección; DUSA_Habilidades_Procesos_Ruta_y_Horas_6.docx
A23: DUSA | B23: Colaboradores | C23: ≈500 (360 en plantas) | D23: dusa-cap087/brief.md

Sheet Datos que faltan
A1: # | B1: Dato que falta | C1: Para qué se necesita | D1: Quién lo puede aportar
A2: 1 | B2: Costo hora de referencia en dólares, validado con Wilmer | C2: Valor en dinero de las horas recuperadas | D2: Wilmer / Finanzas
A3: 2 | B3: Horas productivas por posición al mes | C3: Convertir horas recuperadas en posiciones | D3: Recursos Humanos de DUSA
A4: 3 | B4: Escalas salariales de DUSA por cargo (costo anual cargado por posición) | C4: Costo anual de cada posición | D4: Recursos Humanos / Nómina de DUSA
A5: 4 | B5: Volumen mensual, tiempo actual por ejecución y ejecuciones al mes de cada proceso | C5: Horas actuales al mes (hoy figuran «No declarado» en las fichas) | D5: Las sesiones de levantamiento que tengan el dato; si no existe, la línea base de la semana 1
A6: 5 | B6: Tiempo con la solución por ejecución | C6: Horas recuperadas al mes. Si no hay medición, estimación conservadora marcada como tal | D6: Consultores de Intezia, validado con el líder de cada área
A7: 6 | B7: Dotación equivalente por área (solo se conoce Cuentas por Cobrar: ≈8 personas) | C7: Posiciones que representa hoy el trabajo manual | D7: Líder de cada área
A8: 7 | B8: Posiciones que se reducen y contrataciones que no hará falta hacer, por área | C8: Cuenta de dotación y nómina para los directores | D8: Wilmer y la dirección de DUSA
A9: 8 | B9: Monto de retrabajo, errores, pagos y cobros tardíos, cuando exista el dato | C9: Retorno adicional al tiempo | D9: Finanzas, Tesorería y Nómina de DUSA
A10: 9 | B10: Moneda de los montos de la ficha del agente de parafiscales | C10: Citar el monto pendiente de parafiscales sin error | D10: Nómina de DUSA
A11: 10 | B11: Volumen, estado y horas manuales de cada desarrollo de Sistemas | C11: Tabla de Sistemas del informe | D11: Sistemas de DUSA
A12: 11 | B12: Fichas de levantamiento de las demás áreas (Finanzas, Cuentas por Cobrar, Cuentas por Pagar, Tesorería, Comercial, Gestión de Gente, Beneficios, Gestión Contable) | C12: Cuadro de hallazgos por área y datos duros | D12: Intezia (archivo de sesiones)
